<?xml version="1.0" encoding="utf-8" ?>
<!-- This URDF was automatically created by SolidWorks to URDF Exporter! Originally created by Stephen Brawner (brawner@gmail.com) 
     Commit Version: 1.6.0-4-g7f85cfe  Build Version: 1.6.7995.38578
     For more information, please see http://wiki.ros.org/sw_urdf_exporter -->
<robot name="km1">
    <link name="base_link">
        <inertial>
            <origin xyz="-3.37621983640957E-05 -0.0321978925664446 -0.0469158785173505" rpy="0 0 0" />
            <mass value="0.141735597805843" />
            <inertia ixx="0.000479150143837719" ixy="-9.28437838945723E-08" ixz="-6.96671145359751E-11" iyy="0.000146212203826101" iyz="8.08876695214745E-08" izz="0.000615513009047415" />
        </inertial>
        <visual>
            <origin xyz="0 0 0" rpy="0 0 0" />
            <geometry>
                <mesh filename="package://km1_description/meshes/base_link.STL" />
            </geometry>
            <material name="">
                <color rgba="1 1 0 1" />
            </material>
        </visual>
        <collision>
            <origin xyz="0 0 0" rpy="0 0 0" />
            <geometry>
                <mesh filename="package://km1_description/meshes/base_link.STL" />
            </geometry>
        </collision>
    </link>
    <link name="link1">
        <inertial>
            <origin xyz="4.1386E-05 1.5872E-05 0.0070884" rpy="0 0 0" />
            <mass value="0.08324" />
            <inertia ixx="3.7838E-05" ixy="3.3495E-08" ixz="-2.9218E-08" iyy="4.2147E-05" iyz="3.7187E-10" izz="7.0458E-05" />
        </inertial>
        <visual>
            <origin xyz="0 0 0" rpy="0 0 0" />
            <geometry>
                <mesh filename="package://km1_description/meshes/link1.STL" />
            </geometry>
            <material name="">
                <color rgba="1 1 1 1" />
            </material>
        </visual>
        <collision>
            <origin xyz="0 0 0" rpy="0 0 0" />
            <geometry>
                <mesh filename="package://km1_description/meshes/link1.STL" />
            </geometry>
        </collision>
    </link>
    <joint name="joint1" type="revolute">
        <origin xyz="0 0 0" rpy="0 0 0" />
        <parent link="base_link" />
        <child link="link1" />
        <axis xyz="0 0 1" />
        <limit lower="-3.14" upper="3.14" effort="100" velocity="1" />
    </joint>
    <link name="link2">
        <inertial>
            <origin xyz="-0.025019 0.00034781 0.055909" rpy="0 0 0" />
            <mass value="0.030795" />
            <inertia ixx="6.3213E-06" ixy="4.9123E-08" ixz="-4.7129E-20" iyy="1.2714E-05" iyz="2.9077E-21" izz="1.0137E-05" />
        </inertial>
        <visual>
            <origin xyz="0 0 0" rpy="0 0 0" />
            <geometry>
                <mesh filename="package://km1_description/meshes/link2.STL" />
            </geometry>
            <material name="">
                <color rgba="1 1 1 1" />
            </material>
        </visual>
        <collision>
            <origin xyz="0 0 0" rpy="0 0 0" />
            <geometry>
                <mesh filename="package://km1_description/meshes/link2.STL" />
            </geometry>
        </collision>
    </link>
    <joint name="joint2" type="revolute">
        <origin xyz="0.025998 -0.00031256 0.038401" rpy="0 0 0" />
        <parent link="link1" />
        <child link="link2" />
        <axis xyz="-0.99997 0.0076836 0" />
        <limit lower="-1.57" upper="1.57" effort="100" velocity="1" />
    </joint>
    <link name="link3">
        <inertial>
            <origin xyz="-0.0259120115965228 -0.000655793528643728 0.0430807988531611" rpy="0 0 0" />
            <mass value="0.0732403765810145" />
            <inertia ixx="1.44162069471514E-05" ixy="7.09031863188414E-08" ixz="3.6720264603556E-12" iyy="2.36432715851969E-05" iyz="2.94695886703568E-10" izz="1.42341941025666E-05" />
        </inertial>
        <visual>
            <origin xyz="0 0 0" rpy="0 0 0" />
            <geometry>
                <mesh filename="package://km1_description/meshes/link3.STL" />
            </geometry>
            <material name="">
                <color rgba="0.149019607843137 0.149019607843137 0.149019607843137 1" />
            </material>
        </visual>
        <collision>
            <origin xyz="0 0 0" rpy="0 0 0" />
            <geometry>
                <mesh filename="package://km1_description/meshes/link3.STL" />
            </geometry>
        </collision>
    </link>
    <joint name="joint3" type="revolute">
        <origin xyz="2.3754E-05 0.00031095 0.10527" rpy="0 0 0" />
        <parent link="link2" />
        <child link="link3" />
        <axis xyz="-0.99997 0.0076836 0" />
        <limit lower="-1.57" upper="1.57" effort="100" velocity="1" />
    </joint>
    <link name="link4">
        <inertial>
            <origin xyz="-0.0260993875439493 0.00786849664697727 0.0441546667664198" rpy="0 0 0" />
            <mass value="0.0388631280642024" />
            <inertia ixx="1.2577055269334E-05" ixy="8.42954866877916E-08" ixz="-1.38686981530559E-09" iyy="1.05546590537189E-05" iyz="-4.16343910930148E-07" izz="7.47273370295861E-06" />
        </inertial>
        <visual>
            <origin xyz="0 0 0" rpy="0 0 0" />
            <geometry>
                <mesh filename="package://km1_description/meshes/link4.STL" />
            </geometry>
            <material name="">
                <color rgba="1 1 1 1" />
            </material>
        </visual>
        <collision>
            <origin xyz="0 0 0" rpy="0 0 0" />
            <geometry>
                <mesh filename="package://km1_description/meshes/link4.STL" />
            </geometry>
        </collision>
    </link>
    <joint name="joint4" type="revolute">
        <origin xyz="0 -0.00022558 0.086162" rpy="0 0 0" />
        <parent link="link3" />
        <child link="link4" />
        <axis xyz="-0.99997 0.0076836 0" />
        <limit lower="-1.57" upper="1.57" effort="100" velocity="1" />
    </joint>
    <link name="link5">
        <inertial>
            <origin xyz="0.00306335120564426 0.0170029263519863 0.0271200450555512" rpy="0 0 0" />
            <mass value="0.0392617523984987" />
            <inertia ixx="5.81308817487984E-06" ixy="5.89851879213048E-08" ixz="6.84127833376093E-10" iyy="6.75625821644508E-06" iyz="-8.48632986942009E-08" izz="9.48909371427147E-06" />
        </inertial>
        <visual>
            <origin xyz="0 0 0" rpy="0 0 0" />
            <geometry>
                <mesh filename="package://km1_description/meshes/link5.STL" />
            </geometry>
            <material name="">
                <color rgba="1 1 1 1" />
            </material>
        </visual>
        <collision>
            <origin xyz="0 0 0" rpy="0 0 0" />
            <geometry>
                <mesh filename="package://km1_description/meshes/link5.STL" />
            </geometry>
        </collision>
    </link>
    <joint name="joint5" type="revolute">
        <origin xyz="-0.026265 -0.0018004 0.069565" rpy="0 0 0" />
        <parent link="link4" />
        <child link="link5" />
        <axis xyz="0.00023855 0.031046 -0.99952" />
        <limit lower="-3.14" upper="3.14" effort="100" velocity="1" />
    </joint>
    <link name="link6">
        <inertial>
            <origin xyz="0.00331876371709368 -0.000729411532663427 0.00381417654198601" rpy="0 0 0" />
            <mass value="0.00272937769015017" />
            <inertia ixx="2.00754705810424E-07" ixy="-1.2466097705824E-09" ixz="-1.22615953950637E-07" iyy="4.16745472268266E-07" iyz="3.22582012945341E-09" izz="2.20660752144338E-07" />
        </inertial>
        <visual>
            <origin xyz="0 0 0" rpy="0 0 0" />
            <geometry>
                <mesh filename="package://km1_description/meshes/link6.STL" />
            </geometry>
            <material name="">
                <color rgba="0.792156862745098 0.819607843137255 0.933333333333333 1" />
            </material>
        </visual>
        <collision>
            <origin xyz="0 0 0" rpy="0 0 0" />
            <geometry>
                <mesh filename="package://km1_description/meshes/link6.STL" />
            </geometry>
        </collision>
    </link>
    <joint name="joint6" type="revolute">
        <origin xyz="0.013833 -0.0045297 0.027376" rpy="0 0 0" />
        <parent link="link5" />
        <child link="link6" />
        <axis xyz="-0.02337 0.99925 0.031032" />
        <limit lower="-1.57" upper="1.57" effort="100" velocity="1" />
    </joint>
    <transmission name="trans_joint1">
        <type>transmission_interface/SimpleTransmission</type>
        <joint name="joint1">
            <hardwareInterface>hardware_interface/PositionJointInterface</hardwareInterface>
        </joint>
        <actuator name="joint1_motor">
            <hardwareInterface>hardware_interface/PositionJointInterface</hardwareInterface>
            <mechanicalReduction>1</mechanicalReduction>
        </actuator>
    </transmission>
    <transmission name="trans_joint2">
        <type>transmission_interface/SimpleTransmission</type>
        <joint name="joint2">
            <hardwareInterface>hardware_interface/PositionJointInterface</hardwareInterface>
        </joint>
        <actuator name="joint2_motor">
            <hardwareInterface>hardware_interface/PositionJointInterface</hardwareInterface>
            <mechanicalReduction>1</mechanicalReduction>
        </actuator>
    </transmission>
    <transmission name="trans_joint3">
        <type>transmission_interface/SimpleTransmission</type>
        <joint name="joint3">
            <hardwareInterface>hardware_interface/PositionJointInterface</hardwareInterface>
        </joint>
        <actuator name="joint3_motor">
            <hardwareInterface>hardware_interface/PositionJointInterface</hardwareInterface>
            <mechanicalReduction>1</mechanicalReduction>
        </actuator>
    </transmission>
    <transmission name="trans_joint4">
        <type>transmission_interface/SimpleTransmission</type>
        <joint name="joint4">
            <hardwareInterface>hardware_interface/PositionJointInterface</hardwareInterface>
        </joint>
        <actuator name="joint4_motor">
            <hardwareInterface>hardware_interface/PositionJointInterface</hardwareInterface>
            <mechanicalReduction>1</mechanicalReduction>
        </actuator>
    </transmission>
    <transmission name="trans_joint5">
        <type>transmission_interface/SimpleTransmission</type>
        <joint name="joint5">
            <hardwareInterface>hardware_interface/PositionJointInterface</hardwareInterface>
        </joint>
        <actuator name="joint5_motor">
            <hardwareInterface>hardware_interface/PositionJointInterface</hardwareInterface>
            <mechanicalReduction>1</mechanicalReduction>
        </actuator>
    </transmission>
    <transmission name="trans_joint6">
        <type>transmission_interface/SimpleTransmission</type>
        <joint name="joint6">
            <hardwareInterface>hardware_interface/PositionJointInterface</hardwareInterface>
        </joint>
        <actuator name="joint6_motor">
            <hardwareInterface>hardware_interface/PositionJointInterface</hardwareInterface>
            <mechanicalReduction>1</mechanicalReduction>
        </actuator>
    </transmission>
    <gazebo>
        <plugin name="gazebo_ros_control" filename="libgazebo_ros_control.so">
            <robotNamespace>/km1</robotNamespace>
            <!-- <robotParam>/robot_description</robotParam> -->
            <robotSimType>gazebo_ros_control/DefaultRobotHWSim</robotSimType>
            <legacyModeNS>true</legacyModeNS>
        </plugin>
    </gazebo>
</robot>

